{"content":"<div><div class=\"content\">\n<p>Applications must be able to handle errors that occur during execution in a consistent manner. .NET provides a model for notifying applications of errors in a uniform way: .NET operations indicate failure by throwing exceptions.</p>\n<h2 id=\"exceptions\">Exceptions</h2>\n<p>An exception is any error condition or unexpected behavior that is encountered by an executing program. Exceptions can be thrown because of a fault in your code or in code that you call (such as a shared library), unavailable operating system resources, unexpected conditions that the runtime encounters (such as code that cannot be verified), and so on. Your application can recover from some of these conditions, but not from others. Although you can recover from most application exceptions, you cannot recover from most runtime exceptions.</p>\n<p>In .NET, an exception is an object that inherits from the <a class=\"xref\" href=\"../../api/system.exception\" data-linktype=\"relative-path\">System.Exception</a> class. An exception is thrown from an area of code where a problem has occurred. The exception is passed up the stack until the application handles it or the program terminates.</p>\n<h2 id=\"exceptions-vs-traditional-error-handling-methods\">Exceptions vs. traditional error-handling methods</h2>\n<p>Traditionally, a language&#39;s error-handling model relied on either the language&#39;s unique way of detecting errors and locating handlers for them, or on the error-handling mechanism provided by the operating system. The way .NET implements exception handling provides the following advantages:</p>\n<ul>\n<li><p>Exception throwing and handling works the same for .NET programming languages.</p>\n</li>\n<li><p>Does not require any particular language syntax for handling exceptions, but allows each language to define its own syntax.</p>\n</li>\n<li><p>Exceptions can be thrown across process and even machine boundaries.</p>\n</li>\n<li><p>Exception-handling code can be added to an application to increase program reliability.</p>\n</li>\n</ul>\n<p>Exceptions offer advantages over other methods of error notification, such as return codes. Failures do not go unnoticed because if an exception is thrown and you don&#39;t handle it, the runtime terminates your application. Invalid values do not continue to propagate through the system as a result of code that fails to check for a failure return code. </p>\n<h2 id=\"exception-class-and-properties\">Exception class and properties</h2>\n<p>The <a class=\"xref\" href=\"../../api/system.exception\" data-linktype=\"relative-path\">Exception</a> class is the base class from which exceptions inherit. For example, the <a class=\"xref\" href=\"../../api/system.invalidcastexception\" data-linktype=\"relative-path\">InvalidCastException</a> class hierarchy is as follows:</p>\n<pre class=\"loading\"><code>Object\n  Exception\n    SystemException\n       InvalidCastException\n</code></pre><p>The <a class=\"xref\" href=\"../../api/system.exception\" data-linktype=\"relative-path\">Exception</a> class has the following properties that help make understanding an exception easier.</p>\n<table>\n<thead>\n<tr>\n<th>Property Name</th>\n<th>Description</th>\n</tr>\n</thead>\n<tbody>\n<tr>\n<td><a class=\"xref\" href=\"../../api/system.exception#System_Exception_Data\" data-linktype=\"relative-path\">Data</a></td>\n<td>An <a class=\"xref\" href=\"../../api/system.collections.idictionary\" data-linktype=\"relative-path\">IDictionary</a> that holds arbitrary data in key-value pairs.</td>\n</tr>\n<tr>\n<td><a class=\"xref\" href=\"../../api/system.exception#System_Exception_HelpLink\" data-linktype=\"relative-path\">HelpLink</a></td>\n<td>Can hold a URL (or URN) to a help file that provides extensive information about the cause of an exception.</td>\n</tr>\n<tr>\n<td><a class=\"xref\" href=\"../../api/system.exception#System_Exception_InnerException\" data-linktype=\"relative-path\">InnerException</a></td>\n<td>This property can be used to create and preserve a series of exceptions during exception handling. You can use it to create a new exception that contains previously caught exceptions. The original exception can be captured by the second exception in the <a class=\"xref\" href=\"../../api/system.exception#System_Exception_InnerException\" data-linktype=\"relative-path\">InnerException</a> property, allowing code that handles the second exception to examine the additional information. For example, suppose you have a method that receives an argument that&#39;s improperly formatted.  The code tries to read the argument, but an exception is thrown. The method catches the exception and throws a <a class=\"xref\" href=\"../../api/system.formatexception\" data-linktype=\"relative-path\">FormatException</a>. To improve the caller&#39;s ability to determine the reason an exception is thrown, it is sometimes desirable for a method to catch an exception thrown by a helper routine and then throw an exception more indicative of the error that has occurred. A new and more meaningful exception can be created, where the inner exception reference can be set to the original exception. This more meaningful exception can then be thrown to the caller. Note that with this functionality, you can create a series of linked exceptions that ends with the exception that was thrown first.</td>\n</tr>\n<tr>\n<td><a class=\"xref\" href=\"../../api/system.exception#System_Exception_Message\" data-linktype=\"relative-path\">Message</a></td>\n<td>Provides details about the cause of an exception.</td>\n</tr>\n<tr>\n<td><a class=\"xref\" href=\"../../api/system.exception#System_Exception_Source\" data-linktype=\"relative-path\">Source</a></td>\n<td>Gets or sets the name of the application or the object that causes the error.</td>\n</tr>\n<tr>\n<td><a class=\"xref\" href=\"../../api/system.exception#System_Exception_StackTrace\" data-linktype=\"relative-path\">StackTrace</a></td>\n<td>Contains a stack trace that can be used to determine where an error occurred. The stack trace includes the source file name and program line number if debugging information is available.</td>\n</tr>\n</tbody>\n</table>\n<p>Most of the classes that inherit from <a class=\"xref\" href=\"../../api/system.exception\" data-linktype=\"relative-path\">Exception</a> do not implement additional members or provide additional functionality; they simply inherit from <a class=\"xref\" href=\"../../api/system.exception\" data-linktype=\"relative-path\">Exception</a>. Therefore, the most important information for an exception can be found in the hierarchy of exception classes, the exception name, and the information contained in the exception.</p>\n<p>It is recommended to throw and catch only objects that derive from <a class=\"xref\" href=\"../../api/system.exception\" data-linktype=\"relative-path\">Exception</a>, but you can throw any object that derives from the <a class=\"xref\" href=\"../../api/system.object\" data-linktype=\"relative-path\">Object</a> class as an exception. Note that not all languages support throwing and catching objects that do not derive from <a class=\"xref\" href=\"../../api/system.exception\" data-linktype=\"relative-path\">Exception</a>.</p>\n<h2 id=\"common-exceptions\">Common Exceptions</h2>\n<p>The following table lists some common exceptions with examples of what can cause them.</p>\n<table>\n<thead>\n<tr>\n<th>Exception type</th>\n<th>Base type</th>\n<th>Description</th>\n<th>Example</th>\n</tr>\n</thead>\n<tbody>\n<tr>\n<td><a class=\"xref\" href=\"../../api/system.exception\" data-linktype=\"relative-path\">Exception</a></td>\n<td><a class=\"xref\" href=\"../../api/system.object\" data-linktype=\"relative-path\">Object</a></td>\n<td>Base class for all exceptions.</td>\n<td>None (use a derived class of this exception).</td>\n</tr>\n<tr>\n<td><a class=\"xref\" href=\"../../api/system.indexoutofrangeexception\" data-linktype=\"relative-path\">IndexOutOfRangeException</a></td>\n<td><a class=\"xref\" href=\"../../api/system.exception\" data-linktype=\"relative-path\">Exception</a></td>\n<td>Thrown by the runtime only when an array is indexed improperly.</td>\n<td>Indexing an array outside its valid range: <code>arr[arr.Length+1]</code></td>\n</tr>\n<tr>\n<td><a class=\"xref\" href=\"../../api/system.nullreferenceexception\" data-linktype=\"relative-path\">NullReferenceException</a></td>\n<td><a class=\"xref\" href=\"../../api/system.exception\" data-linktype=\"relative-path\">Exception</a></td>\n<td>Thrown by the runtime only when a null object is referenced.</td>\n<td><code>object o = null; o.ToString();</code></td>\n</tr>\n<tr>\n<td><a class=\"xref\" href=\"../../api/system.invalidoperationexception\" data-linktype=\"relative-path\">InvalidOperationException</a></td>\n<td><a class=\"xref\" href=\"../../api/system.exception\" data-linktype=\"relative-path\">Exception</a></td>\n<td>Thrown by methods when in an invalid state.</td>\n<td>Calling <code>Enumerator.GetNext()</code> after removing an Item from the underlying collection.</td>\n</tr>\n<tr>\n<td><a class=\"xref\" href=\"../../api/system.argumentexception\" data-linktype=\"relative-path\">ArgumentException</a></td>\n<td><a class=\"xref\" href=\"../../api/system.exception\" data-linktype=\"relative-path\">Exception</a></td>\n<td>Base class for all argument exceptions.</td>\n<td>None (use a derived class of this exception).</td>\n</tr>\n<tr>\n<td><a class=\"xref\" href=\"../../api/system.argumentnullexception\" data-linktype=\"relative-path\">ArgumentNullException</a></td>\n<td><a class=\"xref\" href=\"../../api/system.exception\" data-linktype=\"relative-path\">Exception</a></td>\n<td>Thrown by methods that do not allow an argument to be null.</td>\n<td><code>String s = null; &quot;Calculate&quot;.IndexOf (s);</code></td>\n</tr>\n<tr>\n<td><a class=\"xref\" href=\"../../api/system.argumentoutofrangeexception\" data-linktype=\"relative-path\">ArgumentOutOfRangeException</a></td>\n<td><a class=\"xref\" href=\"../../api/system.exception\" data-linktype=\"relative-path\">Exception</a></td>\n<td>Thrown by methods that verify that arguments are in a given range.</td>\n<td><code>String s = &quot;string&quot;; s.Substring(s.Length+1);</code></td>\n</tr>\n</tbody>\n</table>\n<h2 id=\"how-to-use-the-trycatch-block-to-catch-exceptions\">How to use the try/catch block to catch exceptions</h2>\n<p>Place the sections of code that might throw exceptions in a <code>try</code> block and place code that handles exceptions in a <code>catch</code> block. The <code>catch</code> block is a series of statements beginning with the keyword <code>catch</code>, followed by an exception type and an action to be taken.</p>\n<p>The following code example uses a <code>try</code>/<code>catch</code> block to catch a possible exception. The <code>Main</code> method contains a <code>try</code> block with a <a class=\"xref\" href=\"../../api/system.io.streamreader\" data-linktype=\"relative-path\">StreamReader</a> statement that opens a data file called <code>data.txt</code> and writes a string from the file. Following the <code>try</code> block is a <code>catch</code> block that catches any exception that results from the <code>try</code> block.</p>\n<p>C#</p>\n<pre class=\"loading\"><code>using System;\nusing System.IO;\n\npublic class ProcessFile\n{\n    public static void Main()\n    {\n        try\n        {\n            StreamReader sr = File.OpenText(&quot;data.txt&quot;);\n            Console.WriteLine(&quot;The first line of this file is {0}&quot;, sr.ReadLine());\n            sr.Dispose();\n        }\n        catch (Exception e)\n        {\n            Console.WriteLine(&quot;An error occurred: &#39;{0}&#39;&quot;, e);\n        }\n    }\n}\n</code></pre><p>The common language runtime catches exceptions that are not caught by a catch block. Depending on how the runtime is configured, a debug dialog box appears, or the program stops executing and a dialog box with exception information appears, or an error is printed out to STDERR.</p>\n<div class=\"NOTE\"><h5>Note</h5><p>Almost any line of code can cause an exception, particularly exceptions that are thrown by the common language runtime itself, such as <a class=\"xref\" href=\"../../api/system.outofmemoryexception\" data-linktype=\"relative-path\">OutOfMemoryException</a>. Most applications don&#39;t have to deal with these exceptions, but you should be aware of this possibility when writing libraries to be used by others. For suggestions on when to set code in a Try block, see <a href=\"#best-practices-for-exceptions\" data-linktype=\"self-bookmark\">Best Practices for Exceptions</a>.</p>\n</div>\n<h2 id=\"how-to-use-specific-exceptions-in-a-catch-block\">How to use specific exceptions in a Catch block</h2>\n<p>The preceding code example illustrates a basic <code>catch</code> statement that catches any exception. In general, though, it&#39;s good programming practice to catch a specific type of exception rather than use a basic <code>catch</code> statement.</p>\n<p>When an exception occurs, it is passed up the stack and each catch block is given the opportunity to handle it. The order of catch statements is important. Put catch blocks targeted to specific exceptions before a general exception catch block or the compiler might issue an error. The proper catch block is determined by matching the type of the exception to the name of the exception specified in the catch block. If there is no specific catch block, the exception is caught by a general catch block, if one exists.</p>\n<p>The following code example uses a <code>try</code>/<code>catch</code> block to catch an <a class=\"xref\" href=\"../../api/system.invalidcastexception\" data-linktype=\"relative-path\">InvalidCastException</a>. The sample creates a class called <code>Employee</code> with a single property, employee level (<code>Emlevel</code>). A method, <code>PromoteEmployee</code>, takes an object and increments the employee level. An <a class=\"xref\" href=\"../../api/system.invalidcastexception\" data-linktype=\"relative-path\">InvalidCastException</a> occurs when a <a class=\"xref\" href=\"../../api/system.datetime\" data-linktype=\"relative-path\">DateTime</a> instance is passed to the <code>PromoteEmployee</code> method.</p>\n<p>C#</p>\n<pre class=\"loading\"><code>using System;\n\npublic class Employee\n{\n    //Create employee level property.\n    public int Emlevel\n    {\n        get\n        {\n            return(emlevel);\n        }\n        set\n        {\n            emlevel = value;\n        }\n    }\n\n    private int emlevel = 0;\n}\n\npublic class Ex13\n{\n    public static void PromoteEmployee(Object emp)\n    {\n        //Cast object to Employee.\n        Employee e = (Employee) emp;\n        // Increment employee level.\n        e.Emlevel = e.Emlevel + 1;\n    }\n\n    public static void Main()\n    {\n        try\n        {\n            Object o = new Employee();\n            DateTime newyears = new DateTime(2001, 1, 1);\n            //Promote the new employee.\n            PromoteEmployee(o);\n            //Promote DateTime; results in InvalidCastException as newyears is not an employee instance.\n            PromoteEmployee(newyears);\n        }\n        catch (InvalidCastException e)\n        {\n            Console.WriteLine(&quot;Error passing data to PromoteEmployee method. &quot; + e.Message);\n        }\n    }\n}\n</code></pre><h2 id=\"how-to-use-finally-blocks\">How to use finally blocks</h2>\n<p>When an exception occurs, execution stops and control is given to the appropriate exception handler. This often means that lines of code you expect to be executed are bypassed. Some resource cleanup, such as closing a file, needs to be done even if an exception is thrown. To do this, you can use a <code>finally</code> block. A <code>finally</code> block always executes, regardless of whether an exception is thrown.</p>\n<p>The following code example uses a <code>try</code>/<code>catch</code> block to catch an <a class=\"xref\" href=\"../../api/system.argumentoutofrangeexception\" data-linktype=\"relative-path\">ArgumentOutOfRangeException</a>. The <code>Main</code> method creates two arrays and attempts to copy one to the other. The action generates an <a class=\"xref\" href=\"../../api/system.argumentoutofrangeexception\" data-linktype=\"relative-path\">ArgumentOutOfRangeException</a> and the error is written to the console. The <code>finally</code> block executes regardless of the outcome of the copy action.</p>\n<p>C#</p>\n<pre class=\"loading\"><code>using System;\n\nclass ArgumentOutOfRangeExample\n{\n    public static void Main()\n    {\n        int[] array1 = {0, 0};\n        int[] array2 = {0, 0};\n\n        try\n        {\n            Array.Copy(array1, array2, -1);\n        }\n        catch (ArgumentOutOfRangeException e)\n        {\n            Console.WriteLine(&quot;Error: {0}&quot;, e);\n        }\n        finally\n        {\n            Console.WriteLine(&quot;This statement is always executed.&quot;);\n        }\n    }\n}\n</code></pre><h2 id=\"how-to-explicitly-throw-exceptions\">How to explicitly throw exceptions</h2>\n<p>You can explicitly throw an exception using the <code>throw</code> statement. You can also throw a caught exception again using the <code>throw</code> statement. It is good coding practice to add information to an exception that is re-thrown to provide more information when debugging.</p>\n<p>The following code example uses a <code>try</code>/<code>catch</code> block to catch a possible <a class=\"xref\" href=\"../../api/system.io.filenotfoundexception\" data-linktype=\"relative-path\">FileNotFoundException</a>. Following the <code>try</code> block is a <code>catch</code> block that catches the <a class=\"xref\" href=\"../../api/system.io.filenotfoundexception\" data-linktype=\"relative-path\">FileNotFoundException</a> and writes a message to the console if the data file is not found. The next statement is the <code>throw</code> statement that throws a new <a class=\"xref\" href=\"../../api/system.io.filenotfoundexception\" data-linktype=\"relative-path\">FileNotFoundException</a> and adds text information to the exception.</p>\n<p>C#</p>\n<pre class=\"loading\"><code>using System;\nusing System.IO;\n\npublic class ProcessFile\n{\n   public static void Main()\n      {\n      FileStream fs = null;\n      try   \n      {\n         //Opens a text tile.\n         fs = new FileStream(@&quot;C:\\temp\\data.txt&quot;, FileMode.Open);\n         StreamReader sr = new StreamReader(fs);\n         string line;\n\n         //A value is read from the file and output to the console.\n         line = sr.ReadLine();\n         Console.WriteLine(line);\n      }\n      catch(FileNotFoundException e)\n      {\n         Console.WriteLine(&quot;[Data File Missing] {0}&quot;, e);\n         throw new FileNotFoundException(@&quot;[data.txt not in c:\\temp directory]&quot;,e);\n      }\n      finally\n      {\n         if (fs != null)\n            fs.Dispose();\n      }\n   }\n}\n</code></pre><h2 id=\"how-to-create-user-defined-exceptions\">How to create user-defined exceptions</h2>\n<p>.NET provides a hierarchy of exception classes ultimately derived from the base class <a class=\"xref\" href=\"../../api/system.exception\" data-linktype=\"relative-path\">Exception</a>. However, if none of the predefined exceptions meets your needs, you can create your own exception classes by deriving from the <a class=\"xref\" href=\"../../api/system.exception\" data-linktype=\"relative-path\">Exception</a> class.</p>\n<p>When creating your own exceptions, end the class name of the user-defined exception with the word &quot;Exception,&quot; and implement the three common constructors, as shown in the following example. The example defines a new exception class named <code>EmployeeListNotFoundException</code>. The class is derived from <a class=\"xref\" href=\"../../api/system.exception\" data-linktype=\"relative-path\">Exception</a> and includes three constructors.</p>\n<p>C#</p>\n<pre class=\"loading\"><code>using System;\n\npublic class EmployeeListNotFoundException: Exception\n{\n    public EmployeeListNotFoundException()\n    {\n    }\n\n    public EmployeeListNotFoundException(string message)\n        : base(message)\n    {\n    }\n\n    public EmployeeListNotFoundException(string message, Exception inner)\n        : base(message, inner)\n    {\n    }\n}\n</code></pre><div class=\"NOTE\"><h5>Note</h5><p>In situations where you are using remoting, you must ensure that the metadata for any user-defined exceptions is available at the server (callee) and to the client (the proxy object or caller). For more information, see <a href=\"#best-practices-for-exceptions\" data-linktype=\"self-bookmark\">Best practices for exceptions</a>.</p>\n</div>\n<h2 id=\"best-practices-for-exceptions\">Best practices for exceptions</h2>\n<p>A well-designed app handles exceptions and errors to prevent app crashes. This section describes best practices for handling and creating exceptions.</p>\n<h3 id=\"use-trycatchfinally-blocks\">Use try/catch/finally blocks</h3>\n<p>Use <code>try</code>/<code>catch</code>/<code>finally</code> blocks around code that can potentially generate an exception. </p>\n<p>In <code>catch</code> blocks, always order exceptions from the most specific to the least specific.</p>\n<p>Use a <code>finally</code> block to clean up resources, whether you can recover or not.</p>\n<h3 id=\"handle-common-conditions-without-throwing-exceptions\">Handle common conditions without throwing exceptions</h3>\n<p>For conditions that are likely to occur but might trigger an exception, consider handling them in a way that will avoid the exception. For example, if you try to close a connection that is already closed, you&#39;ll get an <code>InvalidOperationException</code>. You can avoid that by using an <code>if</code> statement to check the connection state before trying to close it.</p>\n<p>C#</p>\n<pre class=\"loading\"><code>if (conn.State != ConnectionState.Closed)\n{\n    conn.Close();\n}\n</code></pre><p>If you don&#39;t check connection state before closing, you can catch the <code>InvalidOperationException</code> exception.</p>\n<p>C#</p>\n<pre class=\"loading\"><code>try\n{\n    conn.Close();\n}\ncatch (InvalidOperationException ex)\n{\n    Console.WriteLine(ex.GetType().FullName);\n    Console.WriteLine(ex.Message);\n}\n</code></pre><p>The method to choose depends on how often you expect the event to occur.</p>\n<ul>\n<li><p>Use exception handling if the event doesn&#39;t occur very often, that is, if the event is truly exceptional and indicates an error (such as an unexpected end-of-file). When you use exception handling, less code is executed in normal conditions.</p>\n</li>\n<li><p>Check for error conditions in code if the event happens routinely and could be considered part of normal execution. When you check for common error conditions, less code is executed because you avoid exceptions.</p>\n</li>\n</ul>\n<h3 id=\"design-classes-so-that-exceptions-can-be-avoided\">Design classes so that exceptions can be avoided</h3>\n<p>A class can provide methods or properties that enable you to avoid making a call that would trigger an exception. For example, a <a class=\"xref\" href=\"../../api/system.io.filestream\" data-linktype=\"relative-path\">FileStream</a> class provides methods that help determine whether the end of the file has been reached. These can be used to avoid the exception that is thrown if you read past the end of the file. The following example shows how to read to the end of a file without triggering an exception.</p>\n<p>C#</p>\n<pre class=\"loading\"><code>class FileRead\n{\n    public void ReadAll(FileStream fileToRead)\n    {\n        // This if statement is optional\n        // as it is very unlikely that\n        // the stream would ever be null.\n        if (fileToRead == null)\n        {\n            throw new System.ArgumentNullException();\n        }\n\n        int b;\n\n        // Set the stream position to the beginning of the file.\n        fileToRead.Seek(0, SeekOrigin.Begin);\n\n        // Read each byte to the end of the file.\n        for (int i = 0; i &lt; fileToRead.Length; i++)\n        {\n            b = fileToRead.ReadByte();\n            Console.Write(b.ToString());\n            // Or do something else with the byte.\n        }\n    }\n}\n</code></pre><p>Another way to avoid exceptions is to return null for extremely common error cases instead of throwing an exception. An extremely common error case can be considered normal flow of control. By returning null in these cases, you minimize the performance impact to an app.</p>\n<h3 id=\"throw-exceptions-instead-of-returning-an-error-code\">Throw exceptions instead of returning an error code</h3>\n<p>Exceptions ensure that failures do not go unnoticed because calling code didn&#39;t check a return code. </p>\n<h3 id=\"use-the-predefined-net-exception-types\">Use the predefined .NET exception types</h3>\n<p>Introduce a new exception class only when a predefined one doesn&#39;t apply. For example:</p>\n<ul>\n<li><p>Throw an <a class=\"xref\" href=\"../../api/system.invalidoperationexception\" data-linktype=\"relative-path\">InvalidOperationException</a> exception if a property set or method call is not appropriate given the object&#39;s current state.</p>\n</li>\n<li><p>Throw an <a class=\"xref\" href=\"../../api/system.argumentexception\" data-linktype=\"relative-path\">ArgumentException</a> exception or one of the predefined classes that derive from <a class=\"xref\" href=\"../../api/system.argumentexception\" data-linktype=\"relative-path\">ArgumentException</a> if invalid parameters are passed.</p>\n</li>\n</ul>\n<h3 id=\"end-exception-class-names-with-the-word-exception\">End exception class names with the word <code>Exception</code></h3>\n<p>When a custom exception is necessary, name it appropriately and derive it from the <a class=\"xref\" href=\"../../api/system.exception\" data-linktype=\"relative-path\">Exception</a> class. For example:</p>\n<p>C#</p>\n<pre class=\"loading\"><code>public class MyFileNotFoundException : Exception\n{\n}\n</code></pre><h3 id=\"include-three-constructors-in-custom-exception-classes\">Include three constructors in custom exception classes</h3>\n<p>Use at least the three common constructors when creating your own exception classes: the default constructor, a constructor that takes a string message, and a constructor that takes a string message and an inner exception.</p>\n<ul>\n<li><p><a class=\"xref\" href=\"../../api/system.exception#System_Exception__ctor\" data-linktype=\"relative-path\">Exception()</a>, which uses default values.</p>\n</li>\n<li><p><a class=\"xref\" href=\"../../api/system.exception#System_Exception__ctor_System_String_\" data-linktype=\"relative-path\">Exception(String)</a>, which accepts a string message.</p>\n</li>\n<li><p><a class=\"xref\" href=\"../../api/system.exception#System_Exception__ctor_System_String_System_Exception_\" data-linktype=\"relative-path\">Exception(String,Exception)</a>, which accepts a string message and an inner exception.</p>\n</li>\n</ul>\n<p>For an example, see <a href=\"#how-to-create-user-defined-exceptions\" data-linktype=\"self-bookmark\">How to: Create User-Defined Exceptions</a>.</p>\n<h3 id=\"ensure-that-exception-data-is-available-when-code-executes-remotely\">Ensure that exception data is available when code executes remotely</h3>\n<p>When you create user-defined exceptions, ensure that the metadata for the exceptions is available to code that is executing remotely. </p>\n<p>For example, on .NET runtimes that implement App Domains, exceptions may occur across App domains. Suppose App Domain A creates App Domain B, which executes code that throws an exception. For App Domain A to properly catch and handle the exception, it must be able to find the assembly that contains the exception thrown by App Domain B. If App Domain B throws an exception that is contained in an assembly under its application base, but not under App Domain A&#39;s application base, App Domain A will not be able to find the exception, and the common language runtime will throw a <a class=\"xref\" href=\"../../api/system.io.filenotfoundexception\" data-linktype=\"relative-path\">FileNotFoundException</a> exception. To avoid this situation, you can deploy the assembly that contains the exception information in two ways:</p>\n<ul>\n<li><p>Put the assembly into a common application base shared by both app domains.</p>\n<p>  - or -</p>\n</li>\n<li><p>If the domains do not share a common application base, sign the assembly that contains the exception information with a strong name and deploy the assembly into the global assembly cache.</p>\n</li>\n</ul>\n<h3 id=\"include-a-localized-description-string-in-every-exception\">Include a localized description string in every exception</h3>\n<p>The error message that the user sees is derived from the description string of the exception that was thrown, and not from the name of the exception class.</p>\n<h3 id=\"use-grammatically-correct-error-messages\">Use grammatically correct error messages</h3>\n<p>Write clear sentences and include ending punctuation. Each sentence in a description string of an exception should end in a period. For example, &quot;The log table has overflowed.” would be an appropriate description string.</p>\n<h3 id=\"in-custom-exceptions-provide-additional-properties-as-needed\">In custom exceptions, provide additional properties as needed</h3>\n<p>Provide additional properties for an exception (in addition to the description string) only when there&#39;s a programmatic scenario where the additional information is useful. For example, the <a class=\"xref\" href=\"../../api/system.io.filenotfoundexception\" data-linktype=\"relative-path\">FileNotFoundException</a> provides the <a class=\"xref\" href=\"../../api/system.io.filenotfoundexception#System_IO_FileNotFoundException_FileName\" data-linktype=\"relative-path\">FileName</a> property.</p>\n<h3 id=\"place-throw-statements-so-that-the-stack-trace-will-be-helpful\">Place throw statements so that the stack trace will be helpful</h3>\n<p>The stack trace begins at the statement where the exception is thrown and ends at the <code>catch</code> statement that catches the exception.</p>\n<h3 id=\"use-exception-builder-methods\">Use exception builder methods</h3>\n<p>It is common for a class to throw the same exception from different places in its implementation. To avoid excessive code, use helper methods that create the exception and return it. For example:</p>\n<p>C#</p>\n<pre class=\"loading\"><code>class FileReader\n{\n    private string fileName;\n\n    public FileReader(string path)\n    {\n        fileName = path;\n    }\n\n    public byte[] Read(int bytes)\n    {\n        byte[] results = FileUtils.ReadFromFile(fileName, bytes);\n        if (results == null)\n        {\n            throw NewFileIOException();\n        }\n        return results;\n    }\n\n    FileReaderException NewFileIOException()\n    {\n        string description = &quot;My NewFileIOException Description&quot;;\n\n        return new FileReaderException(description);\n    }\n}\n</code></pre><p>In some cases, it&#39;s more appropriate to use the exception&#39;s constructor to build the exception. An example is a global exception class such as <a class=\"xref\" href=\"../../api/system.argumentexception\" data-linktype=\"relative-path\">ArgumentException</a>, </p>\n<h3 id=\"clean-up-intermediate-results-when-throwing-an-exception\">Clean up intermediate results when throwing an exception</h3>\n<p>Callers should be able to assume that there are no side effects when an exception is thrown from a method. For example, if you have code that transfers money by withdrawing from one account and depositing in another account, and an exception is thrown while executing the deposit, you don&#39;t want the withdrawal to remain in effect.</p>\n<p>C#</p>\n<pre class=\"loading\"><code>public void TransferFunds(Account from, Account to, decimal amount)\n{\n    from.Withdrawal(amount);\n    // If the deposit fails, the withdrawal shouldn&#39;t remain in effect. \n    to.Deposit(amount);\n}\n</code></pre><p>One way to handle this situation is to catch any exceptions thrown by the deposit transaction and roll back the withdrawal.</p>\n<p>C#</p>\n<pre class=\"loading\"><code>private static void TransferFunds(Account from, Account to, decimal amount)\n{\n    string withdrawalTrxID = from.Withdrawal(amount);\n    try\n    {\n        to.Deposit(amount);\n    }\n    catch\n    {\n        from.RollbackTransaction(withdrawalTrxID);\n        throw\n    }\n}\n</code></pre><p>This example illustrates the use of <code>throw</code> to re-throw the original exception, which can make it easier for callers to see the real cause of the problem without having to examine the <a class=\"xref\" href=\"../../api/system.exception#System_Exception_InnerException\" data-linktype=\"relative-path\">InnerException</a> property. An alternative is to throw a new exception and include the original exception as the inner exception:</p>\n<p>C#</p>\n<pre class=\"loading\"><code>catch (Exception ex)\n{\n    from.RollbackTransaction(withdrawalTrxID);\n    throw new Exception(&quot;Withdrawal failed&quot;, ex);\n}\n</code></pre><h2 id=\"see-also\">See Also</h2>\n<p>To learn more about how exceptions work in .NET, see <a href=\"https://github.com/dotnet/coreclr/blob/master/Documentation/botr/exceptions.md\" data-linktype=\"external\">What Every Dev needs to Know About Exceptions in the Runtime</a>.</p>\n</div></div>","outputRootRelativePath":"../../","pageMetadata":"<meta name=\"author\" content=\"mairaw\">\r\n<meta name=\"ms.author\" content=\"mairaw\">\r\n<meta name=\"manager\" content=\"wpickett\">\r\n<meta name=\"breadcrumb_path\" content=\"/dotnet/toc2.json\">\r\n<meta name=\"ms.devlang\" content=\"dotnet\">\r\n<meta name=\"ms.assetid\" content=\"bf116df6-0042-46bf-be13-b69864816210\">\r\n<meta name=\"description\" content=\"Understand how to use exceptions in .NET\">\r\n<meta name=\"keywords\" content=\".NET, .NET Core\">\r\n<meta name=\"ms.topic\" content=\"article\">\r\n<meta name=\"ms.date\" content=\"06/20/2016\">\r\n<meta name=\"ms.technology\" content=\"dotnet-standard\">\r\n<meta name=\"ms.prod\" content=\".net\">\r\n<meta name=\"search.ms_sitename\" content=\"Docs\">\r\n<meta name=\"search.ms_docsetname\" content=\"docs-internal\">\r\n<meta name=\"version\" content=\"0\">\r\n<meta name=\"locale\" content=\"en-us\">\r\n<meta name=\"site_name\" content=\"Docs\">\r\n<meta name=\"search.ms_product\" content=\"MSDN\">\r\n<meta name=\"depot_name\" content=\"MSDN.docs-internal\">\r\n<meta name=\"updated_at\" content=\"2016-12-15 06:00 PM\">\r\n<meta name=\"gitcommit\" content=\"https://github.com/dotnet/docs-internal/blob/90fe68f7f3c4b46502b5d3770b1a2d57c6af748a/docs/standard/exceptions.md\">\r\n<meta name=\"original_content_git_url\" content=\"https://github.com/dotnet/docs-internal/blob/master/docs/standard/exceptions.md\">\r\n<meta name=\"document_id\" content=\"14bdbeaa-9999-4574-1a91-a7a7e8134b3c\">\r\n<meta name=\"pagetype\" content=\"Conceptual\">\r\n<meta name=\"toc_rel\" content=\"../toc2.json\">\r\n","rawMetadata":{"author":"mairaw","ms.author":"mairaw","manager":"wpickett","breadcrumb_path":"/dotnet/toc.json","title":"Handling and throwing exceptions in .NET | Microsoft Docs","ms.devlang":"dotnet","ms.assetid":"bf116df6-0042-46bf-be13-b69864816210","description":"Understand how to use exceptions in .NET","keywords":".NET, .NET Core","ms.topic":"article","ms.date":"06/20/2016","ms.technology":"dotnet-standard","ms.prod":".net","search.ms_sitename":"Docs","search.ms_docsetname":"docs-internal","version":0,"_op_canonicalUrlPrefix":"https://docs.microsoft.com/en-us/dotnet-internal/","locale":"en-us","site_name":"Docs","search.ms_product":"MSDN","_op_openToPublicContributors":false,"depot_name":"MSDN.docs-internal","_op_gitCommitHistory":[{"author_name":"Maira Wenzel","author_email":"mairaw@microsoft.com","committer_name":"GitHub","comitter_email":"noreply@github.com","message":"Metadata updates (#1313)","commit_sha":"90fe68f7f3c4b46502b5d3770b1a2d57c6af748a","commit_date":"2016-12-09 12:40:41 -0800"},{"author_name":"Florian Greinacher","author_email":"post@floriangreinacher.de","committer_name":"GitHub","comitter_email":"noreply@github.com","message":"Better example for ArgumentOutOfRangeException","commit_sha":"9584699ad7e745ae3cb059b1bb8327301c9a3286","commit_date":"2016-09-29 21:08:42 +0200"},{"author_name":"Maira Wenzel","author_email":"mairaw@microsoft.com","committer_name":"GitHub","comitter_email":"noreply@github.com","message":"Changing absolute URLs and formatting of keywords (#922)","commit_sha":"f598ea684b849825d30ccc74f3d755c46e58ba4d","commit_date":"2016-08-24 12:38:31 -0700"},{"author_name":"Petr Onderka","author_email":"gsvick@gmail.com","committer_name":"Maira Wenzel","comitter_email":"mairaw@users.noreply.github.com","message":"Corrected titles and headings (#690)","commit_sha":"17cac6e7690fd2b08d9f5f73060056d14bca13d2","commit_date":"2016-06-28 12:36:36 -0700"},{"author_name":"Tom Dykstra","author_email":"tdykstra@microsoft.com","committer_name":"Rich Lander","comitter_email":"rlander@microsoft.com","message":"exceptions feedback (#637)","commit_sha":"36fa1d2ef302992c97a97bceb3c0ecda1a35a4c7","commit_date":"2016-06-25 14:05:10 -0700"},{"author_name":"Tom Dykstra","author_email":"tdykstra@microsoft.com","committer_name":"GitHub","comitter_email":"noreply@github.com","message":"Finish exception topics migration (#616)","commit_sha":"8ac72605ff040a9cd7720bd06fbb528cc0b2e344","commit_date":"2016-06-24 16:28:09 -0700"}],"updated_at":"2016-12-15 06:00 PM","_op_gitContributorInformation":{"author":{"profile_url":"https://github.com/mairaw","display_name":"Maira Wenzel","id":"12971179"},"contributors":[{"profile_url":"https://github.com/mairaw","display_name":"Maira Wenzel"},{"profile_url":"https://github.com/fgreinacher","display_name":"Florian Greinacher","id":"1540469"},{"profile_url":"https://github.com/svick","display_name":"Petr Onderka","id":"287848"},{"profile_url":"https://github.com/tdykstra","display_name":"Tom Dykstra","id":"1569635"}],"update_at":"12/15/2016"},"gitcommit":"https://github.com/dotnet/docs-internal/blob/90fe68f7f3c4b46502b5d3770b1a2d57c6af748a/docs/standard/exceptions.md","original_content_git_url":"https://github.com/dotnet/docs-internal/blob/master/docs/standard/exceptions.md","open_to_public_contributors":false,"content_git_url":"https://github.com/dotnet/docs/blob/master/docs/standard/exceptions.md","document_id":"14bdbeaa-9999-4574-1a91-a7a7e8134b3c","layout":"Conceptual","pagetype":"Conceptual","canonical_url":"https://docs.microsoft.com/en-us/dotnet/articles/standard/exceptions","toc_asset_id":"articles/toc.json","toc_rel":"../toc.json","_op_ogTitle":"Handling and throwing exceptions in .NET","_op_displayDate":"2016-6-20","_op_displayDate_source":"2016-06-20T00:00:00Z","_op_wordCount":3248,"_op_rawTitle":"<h1 id=\"handling-and-throwing-exceptions-in-net\" sourcefile=\"docs/standard/exceptions.md\" sourcestartlinenumber=\"15\" sourceendlinenumber=\"15\">Handling and throwing exceptions in .NET</h1>","_op_searchScope":[".NET"],"_op_canonicalUrl":"https://docs.microsoft.com/en-us/dotnet/articles/standard/exceptions","fileRelativePath":"articles/standard/exceptions.html"},"themesRelativePathToOutputRoot":"_themes/"}